<?xml version="1.0" encoding="utf-8"?>
<!-- This URDF was automatically created by SolidWorks to URDF Exporter! Originally created by Stephen Brawner (brawner@gmail.com) 
     Commit Version: 1.6.0-4-g7f85cfe  Build Version: 1.6.7995.38578
     For more information, please see http://wiki.ros.org/sw_urdf_exporter -->
<robot
  name="robot_arm">
  <link
    name="base_link">
    <inertial>
      <origin
        xyz="-0.00398828370687043 -0.0775678481202017 -0.0217693819000004"
        rpy="0 0 0" />
      <mass
        value="0.288889380488258" />
      <inertia
        ixx="0.000266474437597533"
        ixy="-1.03865572224056E-20"
        ixz="-4.96308367531816E-21"
        iyy="0.000350648549571195"
        iyz="-2.24091622569824E-21"
        izz="0.000266474437597533" />
    </inertial>
    <visual>
      <origin
        xyz="0 0 0"
        rpy="0 0 0" />
      <geometry>
        <mesh
          filename="package://robot_arm/meshes/base_link.STL" />
      </geometry>
      <material
        name="">
        <color
          rgba="0.792156862745098 0.819607843137255 0.933333333333333 1" />
      </material>
    </visual>
    <collision>
      <origin
        xyz="0 0 0"
        rpy="0 0 0" />
      <geometry>
        <mesh
          filename="package://robot_arm/meshes/base_link.STL" />
      </geometry>
    </collision>
  </link>
  <link
    name="link1">
    <inertial>
      <origin
        xyz="-1.95061009618941E-09 9.91731834142778E-06 0.0156114006190826"
        rpy="0 0 0" />
      <mass
        value="0.0800362555391812" />
      <inertia
        ixx="1.50883578975726E-05"
        ixy="-2.8751596358526E-12"
        ixz="-1.12152865228051E-12"
        iyy="4.16112953755754E-05"
        iyz="9.21897491824461E-09"
        izz="4.48360603626746E-05" />
    </inertial>
    <visual>
      <origin
        xyz="0 0 0"
        rpy="0 0 0" />
      <geometry>
        <mesh
          filename="package://robot_arm/meshes/link1.STL" />
      </geometry>
      <material
        name="">
        <color
          rgba="0.792156862745098 0.819607843137255 0.933333333333333 1" />
      </material>
    </visual>
    <collision>
      <origin
        xyz="0 0 0"
        rpy="0 0 0" />
      <geometry>
        <mesh
          filename="package://robot_arm/meshes/link1.STL" />
      </geometry>
    </collision>
  </link>
  <joint
    name="joint1"
    type="revolute">
    <origin
      xyz="-0.0039883 -0.1105 -0.021769"
      rpy="-1.5708 0.040802 -3.1416" />
    <parent
      link="base_link" />
    <child
      link="link1" />
    <axis
      xyz="0 0 1" />
    <limit
      lower="3.14"
      upper="-3.14"
      effort="100"
      velocity="1" />
  </joint>
  <link
    name="link2">
    <inertial>
      <origin
        xyz="0.0242396860547709 0.000993879258798669 0"
        rpy="0 0 0" />
      <mass
        value="0.0259312994351659" />
      <inertia
        ixx="2.1341902221945E-06"
        ixy="-2.73289237178091E-21"
        ixz="3.91752738105114E-21"
        iyy="1.15888585714462E-05"
        iyz="-3.21084000675938E-22"
        izz="1.19331212252225E-05" />
    </inertial>
    <visual>
      <origin
        xyz="0 0 0"
        rpy="0 0 0" />
      <geometry>
        <mesh
          filename="package://robot_arm/meshes/link2.STL" />
      </geometry>
      <material
        name="">
        <color
          rgba="0.792156862745098 0.819607843137255 0.933333333333333 1" />
      </material>
    </visual>
    <collision>
      <origin
        xyz="0 0 0"
        rpy="0 0 0" />
      <geometry>
        <mesh
          filename="package://robot_arm/meshes/link2.STL" />
      </geometry>
    </collision>
  </link>
  <joint
    name="joint2"
    type="revolute">
    <origin
      xyz="0 0 0.044384"
      rpy="0 -1.3342 -1.5708" />
    <parent
      link="link1" />
    <child
      link="link2" />
    <axis
      xyz="0 1 0" />
    <limit
      lower="3.14"
      upper="-3.14"
      effort="100"
      velocity="1" />
  </joint>
  <link
    name="link3">
    <inertial>
      <origin
        xyz="-0.0412548882668624 -0.00115643002044266 1.0887082901867E-10"
        rpy="0 0 0" />
      <mass
        value="0.0316922868963242" />
      <inertia
        ixx="2.27587345356735E-06"
        ixy="-2.20848023156367E-07"
        ixz="-2.65809384035189E-13"
        iyy="2.22839586326293E-05"
        iyz="-3.49525158461995E-12"
        izz="2.24696947167436E-05" />
    </inertial>
    <visual>
      <origin
        xyz="0 0 0"
        rpy="0 0 0" />
      <geometry>
        <mesh
          filename="package://robot_arm/meshes/link3.STL" />
      </geometry>
      <material
        name="">
        <color
          rgba="0.792156862745098 0.819607843137255 0.933333333333333 1" />
      </material>
    </visual>
    <collision>
      <origin
        xyz="0 0 0"
        rpy="0 0 0" />
      <geometry>
        <mesh
          filename="package://robot_arm/meshes/link3.STL" />
      </geometry>
    </collision>
  </link>
  <joint
    name="joint3"
    type="revolute">
    <origin
      xyz="0.065309 0 0"
      rpy="0 0.5857 3.1416" />
    <parent
      link="link2" />
    <child
      link="link3" />
    <axis
      xyz="0 1 0" />
    <limit
      lower="3.14"
      upper="-3.14"
      effort="100"
      velocity="1" />
  </joint>
  <link
    name="link4">
    <inertial>
      <origin
        xyz="1.36279876272738E-13 0.000393879258798684 0.0148712885499788"
        rpy="0 0 0" />
      <mass
        value="0.00815848070635942" />
      <inertia
        ixx="1.65747192919462E-06"
        ixy="5.3902192813311E-23"
        ixz="2.87858853168454E-21"
        iyy="1.6644698268305E-06"
        iyz="-1.54949351241432E-23"
        izz="2.66471532790001E-07" />
    </inertial>
    <visual>
      <origin
        xyz="0 0 0"
        rpy="0 0 0" />
      <geometry>
        <mesh
          filename="package://robot_arm/meshes/link4.STL" />
      </geometry>
      <material
        name="">
        <color
          rgba="0.792156862745098 0.819607843137255 0.933333333333333 1" />
      </material>
    </visual>
    <collision>
      <origin
        xyz="0 0 0"
        rpy="0 0 0" />
      <geometry>
        <mesh
          filename="package://robot_arm/meshes/link4.STL" />
      </geometry>
    </collision>
  </link>
  <joint
    name="joint4"
    type="revolute">
    <origin
      xyz="-0.091355 0 0"
      rpy="-3.1416 -0.57821 0" />
    <parent
      link="link3" />
    <child
      link="link4" />
    <axis
      xyz="0 1 0" />
    <limit
      lower="3.14"
      upper="-3.14"
      effort="100"
      velocity="1" />
  </joint>
</robot>