<?xml version="1.0"?>
<robot
     xmlns:xacro="http://www.ros.org/wiki/xacro" name="one_DOF_robot">
    <link name="world"/>
    <joint name="glue_robot_to_world" type="fixed">
        <parent link="world"/>
        <child link="link1"/>
    </joint>    

    <link name="link1">
        <inertial>
            <origin xyz="0.0 0.0 0.5" rpy="0.0 0.0 0.0"/>
            <mass value="1.0"/>
            <inertia ixx="1.0" ixy="0.0" ixz="0.0" iyy="1.0" iyz="0.0" izz="1.0"/>
        </inertial>
        <visual>
            <origin xyz="0.0 0.0 0.5" rpy="0.0 0.0 0.0"/>
            <geometry>
                <box size="0.2 0.2 1.0"/>
            </geometry>
        </visual>
        <collision>
            <origin xyz="0.0 0.0 0.5" rpy="0.0 0.0 0.0"/>
            <geometry>
                <box size="0.2 0.2 0.7"/>
            </geometry>
        </collision>
    </link>
    <link name="link2">
        <inertial>
            <origin xyz="0.0 0.0 0.5" rpy="0.0 0.0 0.0"/>
            <mass value="1"/>
            <inertia ixx="0.1" ixy="0.0" ixz="0.0" iyy="0.1" iyz="0.0" izz="0.005"/>
        </inertial>
        <visual>
            <origin xyz="0.0 0.0 0.5" rpy="0.0 0.0 0.0"/>
            <geometry>
                <cylinder radius="0.1" length="1.0"/>
            </geometry>
        </visual>
        <collision>
            <origin xyz="0.0 0.0 0.5" rpy="0.0 0.0 0.0"/>
            <geometry>
                <cylinder radius="0.1" length="1.0"/>
            </geometry>
        </collision>
    </link>
    
    <joint name="joint1" type="prismatic">
        <origin xyz="0.0 0.0 1.0" rpy="0.0 0.0 0.0"/>
        <parent link="link1"/>
        <child link="link2"/>
        <axis xyz="0.0 0.0 1.0"/>
        <limit lower="-1.0" upper="1000.0" effort="0.0" velocity="100.0"/>
        <dynamics damping="10.0"/>
    </joint>
    <transmission name="tran1">
        <type>transmission_interface/SimpleTransmission</type>
        <joint name="joint1">
        <hardwareInterface>EffortJointInterface</hardwareInterface>
        </joint>
        <actuator name="motor1">
        <hardwareInterface>EffortJointInterface</hardwareInterface>
        <mechanicalReduction>1</mechanicalReduction>
        </actuator>
    </transmission>
    <gazebo>
        <plugin name="gazebo_ros_control" filename="libgazebo_ros_control.so">
        <robotNamespace>/one_DOF_robot</robotNamespace>
        </plugin>
    </gazebo>

    <!--model a f/t sensor; set up a link and a joint -->
    <link name="ft_sensor_link">
        <collision>
            <origin xyz="0 0 0" rpy="0 0 0"/>
            <geometry>
                <cylinder length="0.005" radius="0.05"/>
            </geometry>
        </collision>

        <visual>
            <origin xyz="0 0 0" rpy="0 0 0" />
            <geometry>
                <cylinder length="0.005" radius="0.05"/>
            </geometry>
        </visual>

        <inertial>
            <mass value="0.01" />
            <origin xyz="0 0 0" rpy="0 0 0"/>
            <inertia ixx="0.01" ixy="0" ixz="0" iyy="0.01" iyz="0" izz="0.01" />
        </inertial>
    </link>
    
    <!--ideally, this would be a static joint; until fixed in gazebo, must have dynamic jnt-->
    <joint name="ft_sensor_jnt" type="prismatic">
        <parent link="link2"/>
        <child link="ft_sensor_link"/>
        <origin xyz="0 0 1" rpy="0 0 0"/>
        <axis xyz="0 0 1"/>
        <limit effort="1000.0" lower="0" upper="0.0" velocity="0.01"/>
        <dynamics damping="1.0"/>    
    </joint>


    <!-- Enable the Joint Feedback -->
    <gazebo reference="ft_sensor_jnt">
        <provideFeedback>true</provideFeedback>
    </gazebo>
    <!-- The ft_sensor plugin -->
    <gazebo>
        <plugin name="ft_sensor" filename="libgazebo_ros_ft_sensor.so">
            <updateRate>1000.0</updateRate>
            <topicName>ft_sensor_topic</topicName>
            <jointName>ft_sensor_jnt</jointName>
        </plugin>
    </gazebo>    
</robot>